Workbook

Sheet Intermediate
A1: Course name | B1: Uni | C1: Label | D1: Requirements | E1: Architecture | F1: Design | G1: Construction & Programming *** | H1: Testing | I1: Operations | J1: Maintenance | K1: Configuration mgmt | L1: SE management | M1: SE process | N1: SE models* | O1: SW Security | P1: SE economics | Q1: Verification** | R1: Progr. Language design**
A2: AppLab | B2: OU | C2: =_xlfn.CONCAT(B2, " ", A2) -> OU AppLab
A3: Concepten van programmeertalen | B3: OU | C3: =_xlfn.CONCAT(B3, " ", A3) -> OU Concepten van programmeertalen | R3: X
A4: Functioneel programmeren | B4: OU | C4: =_xlfn.CONCAT(B4, " ", A4) -> OU Functioneel programmeren | G4: X
A5: Geavanceerd objectgeoriënteerd programmeren | B5: OU | C5: =_xlfn.CONCAT(B5, " ", A5) -> OU Geavanceerd objectgeoriënteerd programmeren | F5: X | G5: X
A6: Model-driven development | B6: OU | C6: =_xlfn.CONCAT(B6, " ", A6) -> OU Model-driven development | F6: X | G6: X | N6: X
A7: Objectgeoriënteerd analyseren en ontwerpen | B7: OU | C7: =_xlfn.CONCAT(B7, " ", A7) -> OU Objectgeoriënteerd analyseren en ontwerpen | D7: X | F7: X | M7: X | N7: X
A8: Objectgeoriënteerd programmeren | B8: OU | C8: =_xlfn.CONCAT(B8, " ", A8) -> OU Objectgeoriënteerd programmeren | G8: X
A9: Practicum ontwerpen en implementeren | B9: OU | C9: =_xlfn.CONCAT(B9, " ", A9) -> OU Practicum ontwerpen en implementeren
A10: Software engineering | B10: OU | C10: =_xlfn.CONCAT(B10, " ", A10) -> OU Software engineering
A11: Software testen | B11: OU | C11: =_xlfn.CONCAT(B11, " ", A11) -> OU Software testen | H11: X | I11: X | K11: X
A12: Design for change | B12: OU | C12: =_xlfn.CONCAT(B12, " ", A12) -> OU Design for change | F12: X | G12: X | N12: X
A13: Software Architecture | B13: OU | C13: =_xlfn.CONCAT(B13, " ", A13) -> OU Software Architecture | D13: X | E13: X
A14: Software quality management | B14: OU | C14: =_xlfn.CONCAT(B14, " ", A14) -> OU Software quality management | G14: X | J14: X | M14: X
A15: Software security | B15: OU | C15: =_xlfn.CONCAT(B15, " ", A15) -> OU Software security | O15: X
A16: System verification and testing | B16: OU | C16: =_xlfn.CONCAT(B16, " ", A16) -> OU System verification and testing | H16: X | Q16: X
A17: Functional Programming | B17: RU | C17: =_xlfn.CONCAT(B17, " ", A17) -> RU Functional Programming | G17: X | N17: X
A18: Object Oriented Programming | B18: RU | C18: =_xlfn.CONCAT(B18, " ", A18) -> RU Object Oriented Programming | F18: X | G18: X
A19: Requirements Engineering and design | B19: RU | C19: =_xlfn.CONCAT(B19, " ", A19) -> RU Requirements Engineering and design | D19: X | L19: X
A20: Research & Development project | B20: RU | C20: =_xlfn.CONCAT(B20, " ", A20) -> RU Research & Development project
A21: Semantics and Rewriting | B21: RU | C21: =_xlfn.CONCAT(B21, " ", A21) -> RU Semantics and Rewriting | R21: X
A22: Software Engineering | B22: RU | C22: =_xlfn.CONCAT(B22, " ", A22) -> RU Software Engineering
A23: Software verification | B23: RU | C23: =_xlfn.CONCAT(B23, " ", A23) -> RU Software verification | H23: X | N23: X | Q23: X
A24: Imperative programming | B24: RU | C24: =_xlfn.CONCAT(B24, " ", A24) -> RU Imperative programming | G24: X
A25: Advanced Programming | B25: RU | C25: =_xlfn.CONCAT(B25, " ", A25) -> RU Advanced Programming | G25: X | R25: X
A26: Compiler construction | B26: RU | C26: =_xlfn.CONCAT(B26, " ", A26) -> RU Compiler construction | R26: X
A27: Model checking | B27: RU | C27: =_xlfn.CONCAT(B27, " ", A27) -> RU Model checking | Q27: X
A28: Program verification with types and logic | B28: RU | C28: =_xlfn.CONCAT(B28, " ", A28) -> RU Program verification with types and logic | Q28: X | R28: X
A29: Research Seminar Software Science | B29: RU | C29: =_xlfn.CONCAT(B29, " ", A29) -> RU Research Seminar Software Science
A30: Software Development Entrepreneurship | B30: RU | C30: =_xlfn.CONCAT(B30, " ", A30) -> RU Software Development Entrepreneurship | L30: X | M30: X | P30: X
A31: Software Product Lines | B31: RU | C31: =_xlfn.CONCAT(B31, " ", A31) -> RU Software Product Lines | E31: X | I31: X | L31: X
A32: Software Security | B32: RU | C32: =_xlfn.CONCAT(B32, " ", A32) -> RU Software Security | O32: X
A33: Systems Development Management | B33: RU | C33: =_xlfn.CONCAT(B33, " ", A33) -> RU Systems Development Management | I33: X | L33: X | M33: X
A34: Testing Techniques | B34: RU | C34: =_xlfn.CONCAT(B34, " ", A34) -> RU Testing Techniques | H34: X | M34: X | N34: X
A35: Type Theory and Coq | B35: RU | C35: =_xlfn.CONCAT(B35, " ", A35) -> RU Type Theory and Coq | Q35: X | R35: X
A36: Advanced Object Oriented Programming | B36: RUG | C36: =_xlfn.CONCAT(B36, " ", A36) -> RUG Advanced Object Oriented Programming | F36: X | G36: X | K36: X | M36: X
A37: Advanced programming in C++ | B37: RUG | C37: =_xlfn.CONCAT(B37, " ", A37) -> RUG Advanced programming in C++ | G37: X
A38: Compiler Construction | B38: RUG | C38: =_xlfn.CONCAT(B38, " ", A38) -> RUG Compiler Construction | R38: X
A39: Functional Programming | B39: RUG | C39: =_xlfn.CONCAT(B39, " ", A39) -> RUG Functional Programming | G39: X
A40: Introduction to Scientific Computing | B40: RUG | C40: =_xlfn.CONCAT(B40, " ", A40) -> RUG Introduction to Scientific Computing | G40: X
...

Sheet Final
A1: Course name | B1: Uni | C1: Label | D1: Requirements | E1: Architecture | F1: Design | G1: Construction & Programming *** | H1: Testing | I1: Operations | J1: Maintenance | K1: Configuration mgmt | L1: SE management | M1: SE process | N1: SE models* | O1: SW Security | P1: SE economics | Q1: Verification** | R1: Progr. Language design** | T1: Requirements | U1: Architecture | V1: Design | W1: Construction & Programming *** | X1: Testing | Y1: Operations | Z1: Maintenance | AA1: Configuration mgmt | AB1: SE management | AC1: SE process | AD1: SE models* | AE1: SW Security | AF1: SE economics | AG1: Verification** | AH1: Progr. Language design**
A2: AppLab | B2: OU | C2: =_xlfn.CONCAT(B2, " ", A2) -> OU AppLab | T2: =IF(VLOOKUP($C2,Intermediate!$C$2:$R$208,2,FALSE)=D2, "", IF(D2="x","+", "-")) | U2: =IF(VLOOKUP($C2,Intermediate!$C$2:$R$208,3,FALSE)=E2, "", IF(E2="x","+", "-")) | V2: =IF(VLOOKUP($C2,Intermediate!$C$2:$R$208,4,FALSE)=F2, "", IF(F2="x","+", "-")) | W2: =IF(VLOOKUP($C2,Intermediate!$C$2:$R$208,5,FALSE)=G2, "", IF(G2="x","+", "-")) | X2: =IF(VLOOKUP($C2,Intermediate!$C$2:$R$208,6,FALSE)=H2, "", IF(H2="x","+", "-")) | Y2: =IF(VLOOKUP($C2,Intermediate!$C$2:$R$208,7,FALSE)=I2, "", IF(I2="x","+", "-")) | Z2: =IF(VLOOKUP($C2,Intermediate!$C$2:$R$208,8,FALSE)=J2, "", IF(J2="x","+", "-")) | AA2: =IF(VLOOKUP($C2,Intermediate!$C$2:$R$208,9,FALSE)=K2, "", IF(K2="x","+", "-")) | AB2: =IF(VLOOKUP($C2,Intermediate!$C$2:$R$208,10,FALSE)=L2, "", IF(L2="x","+", "-")) | AC2: =IF(VLOOKUP($C2,Intermediate!$C$2:$R$208,11,FALSE)=M2, "", IF(M2="x","+", "-")) | AD2: =IF(VLOOKUP($C2,Intermediate!$C$2:$R$208,12,FALSE)=N2, "", IF(N2="x","+", "-")) | AE2: =IF(VLOOKUP($C2,Intermediate!$C$2:$R$208,13,FALSE)=O2, "", IF(O2="x","+", "-")) | AF2: =IF(VLOOKUP($C2,Intermediate!$C$2:$R$208,14,FALSE)=P2, "", IF(P2="x","+", "-")) | AG2: =IF(VLOOKUP($C2,Intermediate!$C$2:$R$208,15,FALSE)=Q2, "", IF(Q2="x","+", "-")) | AH2: =IF(VLOOKUP($C2,Intermediate!$C$2:$R$208,16,FALSE)=R2, "", IF(R2="x","+", "-"))
A3: Concepten van programmeertalen | B3: OU | C3: =_xlfn.CONCAT(B3, " ", A3) -> OU Concepten van programmeertalen | R3: X | T3: =IF(VLOOKUP($C3,Intermediate!$C$2:$R$208,2,FALSE)=D3, "", IF(D3="x","+", "-")) | U3: =IF(VLOOKUP($C3,Intermediate!$C$2:$R$208,3,FALSE)=E3, "", IF(E3="x","+", "-")) | V3: =IF(VLOOKUP($C3,Intermediate!$C$2:$R$208,4,FALSE)=F3, "", IF(F3="x","+", "-")) | W3: =IF(VLOOKUP($C3,Intermediate!$C$2:$R$208,5,FALSE)=G3, "", IF(G3="x","+", "-")) | X3: =IF(VLOOKUP($C3,Intermediate!$C$2:$R$208,6,FALSE)=H3, "", IF(H3="x","+", "-")) | Y3: =IF(VLOOKUP($C3,Intermediate!$C$2:$R$208,7,FALSE)=I3, "", IF(I3="x","+", "-")) | Z3: =IF(VLOOKUP($C3,Intermediate!$C$2:$R$208,8,FALSE)=J3, "", IF(J3="x","+", "-")) | AA3: =IF(VLOOKUP($C3,Intermediate!$C$2:$R$208,9,FALSE)=K3, "", IF(K3="x","+", "-")) | AB3: =IF(VLOOKUP($C3,Intermediate!$C$2:$R$208,10,FALSE)=L3, "", IF(L3="x","+", "-")) | AC3: =IF(VLOOKUP($C3,Intermediate!$C$2:$R$208,11,FALSE)=M3, "", IF(M3="x","+", "-")) | AD3: =IF(VLOOKUP($C3,Intermediate!$C$2:$R$208,12,FALSE)=N3, "", IF(N3="x","+", "-")) | AE3: =IF(VLOOKUP($C3,Intermediate!$C$2:$R$208,13,FALSE)=O3, "", IF(O3="x","+", "-")) | AF3: =IF(VLOOKUP($C3,Intermediate!$C$2:$R$208,14,FALSE)=P3, "", IF(P3="x","+", "-")) | AG3: =IF(VLOOKUP($C3,Intermediate!$C$2:$R$208,15,FALSE)=Q3, "", IF(Q3="x","+", "-")) | AH3: =IF(VLOOKUP($C3,Intermediate!$C$2:$R$208,16,FALSE)=R3, "", IF(R3="x","+", "-"))
A4: Functioneel programmeren | B4: OU | C4: =_xlfn.CONCAT(B4, " ", A4) -> OU Functioneel programmeren | G4: X | T4: =IF(VLOOKUP($C4,Intermediate!$C$2:$R$208,2,FALSE)=D4, "", IF(D4="x","+", "-")) | U4: =IF(VLOOKUP($C4,Intermediate!$C$2:$R$208,3,FALSE)=E4, "", IF(E4="x","+", "-")) | V4: =IF(VLOOKUP($C4,Intermediate!$C$2:$R$208,4,FALSE)=F4, "", IF(F4="x","+", "-")) | W4: =IF(VLOOKUP($C4,Intermediate!$C$2:$R$208,5,FALSE)=G4, "", IF(G4="x","+", "-")) | X4: =IF(VLOOKUP($C4,Intermediate!$C$2:$R$208,6,FALSE)=H4, "", IF(H4="x","+", "-")) | Y4: =IF(VLOOKUP($C4,Intermediate!$C$2:$R$208,7,FALSE)=I4, "", IF(I4="x","+", "-")) | Z4: =IF(VLOOKUP($C4,Intermediate!$C$2:$R$208,8,FALSE)=J4, "", IF(J4="x","+", "-")) | AA4: =IF(VLOOKUP($C4,Intermediate!$C$2:$R$208,9,FALSE)=K4, "", IF(K4="x","+", "-")) | AB4: =IF(VLOOKUP($C4,Intermediate!$C$2:$R$208,10,FALSE)=L4, "", IF(L4="x","+", "-")) | AC4: =IF(VLOOKUP($C4,Intermediate!$C$2:$R$208,11,FALSE)=M4, "", IF(M4="x","+", "-")) | AD4: =IF(VLOOKUP($C4,Intermediate!$C$2:$R$208,12,FALSE)=N4, "", IF(N4="x","+", "-")) | AE4: =IF(VLOOKUP($C4,Intermediate!$C$2:$R$208,13,FALSE)=O4, "", IF(O4="x","+", "-")) | AF4: =IF(VLOOKUP($C4,Intermediate!$C$2:$R$208,14,FALSE)=P4, "", IF(P4="x","+", "-")) | AG4: =IF(VLOOKUP($C4,Intermediate!$C$2:$R$208,15,FALSE)=Q4, "", IF(Q4="x","+", "-")) | AH4: =IF(VLOOKUP($C4,Intermediate!$C$2:$R$208,16,FALSE)=R4, "", IF(R4="x","+", "-"))
A5: Geavanceerd objectgeoriënteerd programmeren | B5: OU | C5: =_xlfn.CONCAT(B5, " ", A5) -> OU Geavanceerd objectgeoriënteerd programmeren | F5: X | G5: X | T5: =IF(VLOOKUP($C5,Intermediate!$C$2:$R$208,2,FALSE)=D5, "", IF(D5="x","+", "-")) | U5: =IF(VLOOKUP($C5,Intermediate!$C$2:$R$208,3,FALSE)=E5, "", IF(E5="x","+", "-")) | V5: =IF(VLOOKUP($C5,Intermediate!$C$2:$R$208,4,FALSE)=F5, "", IF(F5="x","+", "-")) | W5: =IF(VLOOKUP($C5,Intermediate!$C$2:$R$208,5,FALSE)=G5, "", IF(G5="x","+", "-")) | X5: =IF(VLOOKUP($C5,Intermediate!$C$2:$R$208,6,FALSE)=H5, "", IF(H5="x","+", "-")) | Y5: =IF(VLOOKUP($C5,Intermediate!$C$2:$R$208,7,FALSE)=I5, "", IF(I5="x","+", "-")) | Z5: =IF(VLOOKUP($C5,Intermediate!$C$2:$R$208,8,FALSE)=J5, "", IF(J5="x","+", "-")) | AA5: =IF(VLOOKUP($C5,Intermediate!$C$2:$R$208,9,FALSE)=K5, "", IF(K5="x","+", "-")) | AB5: =IF(VLOOKUP($C5,Intermediate!$C$2:$R$208,10,FALSE)=L5, "", IF(L5="x","+", "-")) | AC5: =IF(VLOOKUP($C5,Intermediate!$C$2:$R$208,11,FALSE)=M5, "", IF(M5="x","+", "-")) | AD5: =IF(VLOOKUP($C5,Intermediate!$C$2:$R$208,12,FALSE)=N5, "", IF(N5="x","+", "-")) | AE5: =IF(VLOOKUP($C5,Intermediate!$C$2:$R$208,13,FALSE)=O5, "", IF(O5="x","+", "-")) | AF5: =IF(VLOOKUP($C5,Intermediate!$C$2:$R$208,14,FALSE)=P5, "", IF(P5="x","+", "-")) | AG5: =IF(VLOOKUP($C5,Intermediate!$C$2:$R$208,15,FALSE)=Q5, "", IF(Q5="x","+", "-")) | AH5: =IF(VLOOKUP($C5,Intermediate!$C$2:$R$208,16,FALSE)=R5, "", IF(R5="x","+", "-"))
A6: Model-driven development | B6: OU | C6: =_xlfn.CONCAT(B6, " ", A6) -> OU Model-driven development | F6: X | G6: X | N6: X | T6: =IF(VLOOKUP($C6,Intermediate!$C$2:$R$208,2,FALSE)=D6, "", IF(D6="x","+", "-")) | U6: =IF(VLOOKUP($C6,Intermediate!$C$2:$R$208,3,FALSE)=E6, "", IF(E6="x","+", "-")) | V6: =IF(VLOOKUP($C6,Intermediate!$C$2:$R$208,4,FALSE)=F6, "", IF(F6="x","+", "-")) | W6: =IF(VLOOKUP($C6,Intermediate!$C$2:$R$208,5,FALSE)=G6, "", IF(G6="x","+", "-")) | X6: =IF(VLOOKUP($C6,Intermediate!$C$2:$R$208,6,FALSE)=H6, "", IF(H6="x","+", "-")) | Y6: =IF(VLOOKUP($C6,Intermediate!$C$2:$R$208,7,FALSE)=I6, "", IF(I6="x","+", "-")) | Z6: =IF(VLOOKUP($C6,Intermediate!$C$2:$R$208,8,FALSE)=J6, "", IF(J6="x","+", "-")) | AA6: =IF(VLOOKUP($C6,Intermediate!$C$2:$R$208,9,FALSE)=K6, "", IF(K6="x","+", "-")) | AB6: =IF(VLOOKUP($C6,Intermediate!$C$2:$R$208,10,FALSE)=L6, "", IF(L6="x","+", "-")) | AC6: =IF(VLOOKUP($C6,Intermediate!$C$2:$R$208,11,FALSE)=M6, "", IF(M6="x","+", "-")) | AD6: =IF(VLOOKUP($C6,Intermediate!$C$2:$R$208,12,FALSE)=N6, "", IF(N6="x","+", "-")) | AE6: =IF(VLOOKUP($C6,Intermediate!$C$2:$R$208,13,FALSE)=O6, "", IF(O6="x","+", "-")) | AF6: =IF(VLOOKUP($C6,Intermediate!$C$2:$R$208,14,FALSE)=P6, "", IF(P6="x","+", "-")) | AG6: =IF(VLOOKUP($C6,Intermediate!$C$2:$R$208,15,FALSE)=Q6, "", IF(Q6="x","+", "-")) | AH6: =IF(VLOOKUP($C6,Intermediate!$C$2:$R$208,16,FALSE)=R6, "", IF(R6="x","+", "-"))
A7: Objectgeoriënteerd analyseren en ontwerpen | B7: OU | C7: =_xlfn.CONCAT(B7, " ", A7) -> OU Objectgeoriënteerd analyseren en ontwerpen | D7: X | F7: X | M7: X | N7: X | T7: =IF(VLOOKUP($C7,Intermediate!$C$2:$R$208,2,FALSE)=D7, "", IF(D7="x","+", "-")) | U7: =IF(VLOOKUP($C7,Intermediate!$C$2:$R$208,3,FALSE)=E7, "", IF(E7="x","+", "-")) | V7: =IF(VLOOKUP($C7,Intermediate!$C$2:$R$208,4,FALSE)=F7, "", IF(F7="x","+", "-")) | W7: =IF(VLOOKUP($C7,Intermediate!$C$2:$R$208,5,FALSE)=G7, "", IF(G7="x","+", "-")) | X7: =IF(VLOOKUP($C7,Intermediate!$C$2:$R$208,6,FALSE)=H7, "", IF(H7="x","+", "-")) | Y7: =IF(VLOOKUP($C7,Intermediate!$C$2:$R$208,7,FALSE)=I7, "", IF(I7="x","+", "-")) | Z7: =IF(VLOOKUP($C7,Intermediate!$C$2:$R$208,8,FALSE)=J7, "", IF(J7="x","+", "-")) | AA7: =IF(VLOOKUP($C7,Intermediate!$C$2:$R$208,9,FALSE)=K7, "", IF(K7="x","+", "-")) | AB7: =IF(VLOOKUP($C7,Intermediate!$C$2:$R$208,10,FALSE)=L7, "", IF(L7="x","+", "-")) | AC7: =IF(VLOOKUP($C7,Intermediate!$C$2:$R$208,11,FALSE)=M7, "", IF(M7="x","+", "-")) | AD7: =IF(VLOOKUP($C7,Intermediate!$C$2:$R$208,12,FALSE)=N7, "", IF(N7="x","+", "-")) | AE7: =IF(VLOOKUP($C7,Intermediate!$C$2:$R$208,13,FALSE)=O7, "", IF(O7="x","+", "-")) | AF7: =IF(VLOOKUP($C7,Intermediate!$C$2:$R$208,14,FALSE)=P7, "", IF(P7="x","+", "-")) | AG7: =IF(VLOOKUP($C7,Intermediate!$C$2:$R$208,15,FALSE)=Q7, "", IF(Q7="x","+", "-")) | AH7: =IF(VLOOKUP($C7,Intermediate!$C$2:$R$208,16,FALSE)=R7, "", IF(R7="x","+", "-"))
A8: Objectgeoriënteerd programmeren | B8: OU | C8: =_xlfn.CONCAT(B8, " ", A8) -> OU Objectgeoriënteerd programmeren | G8: X | T8: =IF(VLOOKUP($C8,Intermediate!$C$2:$R$208,2,FALSE)=D8, "", IF(D8="x","+", "-")) | U8: =IF(VLOOKUP($C8,Intermediate!$C$2:$R$208,3,FALSE)=E8, "", IF(E8="x","+", "-")) | V8: =IF(VLOOKUP($C8,Intermediate!$C$2:$R$208,4,FALSE)=F8, "", IF(F8="x","+", "-")) | W8: =IF(VLOOKUP($C8,Intermediate!$C$2:$R$208,5,FALSE)=G8, "", IF(G8="x","+", "-")) | X8: =IF(VLOOKUP($C8,Intermediate!$C$2:$R$208,6,FALSE)=H8, "", IF(H8="x","+", "-")) | Y8: =IF(VLOOKUP($C8,Intermediate!$C$2:$R$208,7,FALSE)=I8, "", IF(I8="x","+", "-")) | Z8: =IF(VLOOKUP($C8,Intermediate!$C$2:$R$208,8,FALSE)=J8, "", IF(J8="x","+", "-")) | AA8: =IF(VLOOKUP($C8,Intermediate!$C$2:$R$208,9,FALSE)=K8, "", IF(K8="x","+", "-")) | AB8: =IF(VLOOKUP($C8,Intermediate!$C$2:$R$208,10,FALSE)=L8, "", IF(L8="x","+", "-")) | AC8: =IF(VLOOKUP($C8,Intermediate!$C$2:$R$208,11,FALSE)=M8, "", IF(M8="x","+", "-")) | AD8: =IF(VLOOKUP($C8,Intermediate!$C$2:$R$208,12,FALSE)=N8, "", IF(N8="x","+", "-")) | AE8: =IF(VLOOKUP($C8,Intermediate!$C$2:$R$208,13,FALSE)=O8, "", IF(O8="x","+", "-")) | AF8: =IF(VLOOKUP($C8,Intermediate!$C$2:$R$208,14,FALSE)=P8, "", IF(P8="x","+", "-")) | AG8: =IF(VLOOKUP($C8,Intermediate!$C$2:$R$208,15,FALSE)=Q8, "", IF(Q8="x","+", "-")) | AH8: =IF(VLOOKUP($C8,Intermediate!$C$2:$R$208,16,FALSE)=R8, "", IF(R8="x","+", "-"))
A9: Practicum ontwerpen en implementeren | B9: OU | C9: =_xlfn.CONCAT(B9, " ", A9) -> OU Practicum ontwerpen en implementeren | T9: =IF(VLOOKUP($C9,Intermediate!$C$2:$R$208,2,FALSE)=D9, "", IF(D9="x","+", "-")) | U9: =IF(VLOOKUP($C9,Intermediate!$C$2:$R$208,3,FALSE)=E9, "", IF(E9="x","+", "-")) | V9: =IF(VLOOKUP($C9,Intermediate!$C$2:$R$208,4,FALSE)=F9, "", IF(F9="x","+", "-")) | W9: =IF(VLOOKUP($C9,Intermediate!$C$2:$R$208,5,FALSE)=G9, "", IF(G9="x","+", "-")) | X9: =IF(VLOOKUP($C9,Intermediate!$C$2:$R$208,6,FALSE)=H9, "", IF(H9="x","+", "-")) | Y9: =IF(VLOOKUP($C9,Intermediate!$C$2:$R$208,7,FALSE)=I9, "", IF(I9="x","+", "-")) | Z9: =IF(VLOOKUP($C9,Intermediate!$C$2:$R$208,8,FALSE)=J9, "", IF(J9="x","+", "-")) | AA9: =IF(VLOOKUP($C9,Intermediate!$C$2:$R$208,9,FALSE)=K9, "", IF(K9="x","+", "-")) | AB9: =IF(VLOOKUP($C9,Intermediate!$C$2:$R$208,10,FALSE)=L9, "", IF(L9="x","+", "-")) | AC9: =IF(VLOOKUP($C9,Intermediate!$C$2:$R$208,11,FALSE)=M9, "", IF(M9="x","+", "-")) | AD9: =IF(VLOOKUP($C9,Intermediate!$C$2:$R$208,12,FALSE)=N9, "", IF(N9="x","+", "-")) | AE9: =IF(VLOOKUP($C9,Intermediate!$C$2:$R$208,13,FALSE)=O9, "", IF(O9="x","+", "-")) | AF9: =IF(VLOOKUP($C9,Intermediate!$C$2:$R$208,14,FALSE)=P9, "", IF(P9="x","+", "-")) | AG9: =IF(VLOOKUP($C9,Intermediate!$C$2:$R$208,15,FALSE)=Q9, "", IF(Q9="x","+", "-")) | AH9: =IF(VLOOKUP($C9,Intermediate!$C$2:$R$208,16,FALSE)=R9, "", IF(R9="x","+", "-"))
A10: Software engineering | B10: OU | C10: =_xlfn.CONCAT(B10, " ", A10) -> OU Software engineering | T10: =IF(VLOOKUP($C10,Intermediate!$C$2:$R$208,2,FALSE)=D10, "", IF(D10="x","+", "-")) | U10: =IF(VLOOKUP($C10,Intermediate!$C$2:$R$208,3,FALSE)=E10, "", IF(E10="x","+", "-")) | V10: =IF(VLOOKUP($C10,Intermediate!$C$2:$R$208,4,FALSE)=F10, "", IF(F10="x","+", "-")) | W10: =IF(VLOOKUP($C10,Intermediate!$C$2:$R$208,5,FALSE)=G10, "", IF(G10="x","+", "-")) | X10: =IF(VLOOKUP($C10,Intermediate!$C$2:$R$208,6,FALSE)=H10, "", IF(H10="x","+", "-")) | Y10: =IF(VLOOKUP($C10,Intermediate!$C$2:$R$208,7,FALSE)=I10, "", IF(I10="x","+", "-")) | Z10: =IF(VLOOKUP($C10,Intermediate!$C$2:$R$208,8,FALSE)=J10, "", IF(J10="x","+", "-")) | AA10: =IF(VLOOKUP($C10,Intermediate!$C$2:$R$208,9,FALSE)=K10, "", IF(K10="x","+", "-")) | AB10: =IF(VLOOKUP($C10,Intermediate!$C$2:$R$208,10,FALSE)=L10, "", IF(L10="x","+", "-")) | AC10: =IF(VLOOKUP($C10,Intermediate!$C$2:$R$208,11,FALSE)=M10, "", IF(M10="x","+", "-")) | AD10: =IF(VLOOKUP($C10,Intermediate!$C$2:$R$208,12,FALSE)=N10, "", IF(N10="x","+", "-")) | AE10: =IF(VLOOKUP($C10,Intermediate!$C$2:$R$208,13,FALSE)=O10, "", IF(O10="x","+", "-")) | AF10: =IF(VLOOKUP($C10,Intermediate!$C$2:$R$208,14,FALSE)=P10, "", IF(P10="x","+", "-")) | AG10: =IF(VLOOKUP($C10,Intermediate!$C$2:$R$208,15,FALSE)=Q10, "", IF(Q10="x","+", "-")) | AH10: =IF(VLOOKUP($C10,Intermediate!$C$2:$R$208,16,FALSE)=R10, "", IF(R10="x","+", "-"))
A11: Software testen | B11: OU | C11: =_xlfn.CONCAT(B11, " ", A11) -> OU Software testen | H11: X | I11: X | K11: X | T11: =IF(VLOOKUP($C11,Intermediate!$C$2:$R$208,2,FALSE)=D11, "", IF(D11="x","+", "-")) | U11: =IF(VLOOKUP($C11,Intermediate!$C$2:$R$208,3,FALSE)=E11, "", IF(E11="x","+", "-")) | V11: =IF(VLOOKUP($C11,Intermediate!$C$2:$R$208,4,FALSE)=F11, "", IF(F11="x","+", "-")) | W11: =IF(VLOOKUP($C11,Intermediate!$C$2:$R$208,5,FALSE)=G11, "", IF(G11="x","+", "-")) | X11: =IF(VLOOKUP($C11,Intermediate!$C$2:$R$208,6,FALSE)=H11, "", IF(H11="x","+", "-")) | Y11: =IF(VLOOKUP($C11,Intermediate!$C$2:$R$208,7,FALSE)=I11, "", IF(I11="x","+", "-")) | Z11: =IF(VLOOKUP($C11,Intermediate!$C$2:$R$208,8,FALSE)=J11, "", IF(J11="x","+", "-")) | AA11: =IF(VLOOKUP($C11,Intermediate!$C$2:$R$208,9,FALSE)=K11, "", IF(K11="x","+", "-")) | AB11: =IF(VLOOKUP($C11,Intermediate!$C$2:$R$208,10,FALSE)=L11, "", IF(L11="x","+", "-")) | AC11: =IF(VLOOKUP($C11,Intermediate!$C$2:$R$208,11,FALSE)=M11, "", IF(M11="x","+", "-")) | AD11: =IF(VLOOKUP($C11,Intermediate!$C$2:$R$208,12,FALSE)=N11, "", IF(N11="x","+", "-")) | AE11: =IF(VLOOKUP($C11,Intermediate!$C$2:$R$208,13,FALSE)=O11, "", IF(O11="x","+", "-")) | AF11: =IF(VLOOKUP($C11,Intermediate!$C$2:$R$208,14,FALSE)=P11, "", IF(P11="x","+", "-")) | AG11: =IF(VLOOKUP($C11,Intermediate!$C$2:$R$208,15,FALSE)=Q11, "", IF(Q11="x","+", "-")) | AH11: =IF(VLOOKUP($C11,Intermediate!$C$2:$R$208,16,FALSE)=R11, "", IF(R11="x","+", "-"))
A12: Design for change | B12: OU | C12: =_xlfn.CONCAT(B12, " ", A12) -> OU Design for change | F12: X | G12: X | N12: X | T12: =IF(VLOOKUP($C12,Intermediate!$C$2:$R$208,2,FALSE)=D12, "", IF(D12="x","+", "-")) | U12: =IF(VLOOKUP($C12,Intermediate!$C$2:$R$208,3,FALSE)=E12, "", IF(E12="x","+", "-")) | V12: =IF(VLOOKUP($C12,Intermediate!$C$2:$R$208,4,FALSE)=F12, "", IF(F12="x","+", "-")) | W12: =IF(VLOOKUP($C12,Intermediate!$C$2:$R$208,5,FALSE)=G12, "", IF(G12="x","+", "-")) | X12: =IF(VLOOKUP($C12,Intermediate!$C$2:$R$208,6,FALSE)=H12, "", IF(H12="x","+", "-")) | Y12: =IF(VLOOKUP($C12,Intermediate!$C$2:$R$208,7,FALSE)=I12, "", IF(I12="x","+", "-")) | Z12: =IF(VLOOKUP($C12,Intermediate!$C$2:$R$208,8,FALSE)=J12, "", IF(J12="x","+", "-")) | AA12: =IF(VLOOKUP($C12,Intermediate!$C$2:$R$208,9,FALSE)=K12, "", IF(K12="x","+", "-")) | AB12: =IF(VLOOKUP($C12,Intermediate!$C$2:$R$208,10,FALSE)=L12, "", IF(L12="x","+", "-")) | AC12: =IF(VLOOKUP($C12,Intermediate!$C$2:$R$208,11,FALSE)=M12, "", IF(M12="x","+", "-")) | AD12: =IF(VLOOKUP($C12,Intermediate!$C$2:$R$208,12,FALSE)=N12, "", IF(N12="x","+", "-")) | AE12: =IF(VLOOKUP($C12,Intermediate!$C$2:$R$208,13,FALSE)=O12, "", IF(O12="x","+", "-")) | AF12: =IF(VLOOKUP($C12,Intermediate!$C$2:$R$208,14,FALSE)=P12, "", IF(P12="x","+", "-")) | AG12: =IF(VLOOKUP($C12,Intermediate!$C$2:$R$208,15,FALSE)=Q12, "", IF(Q12="x","+", "-")) | AH12: =IF(VLOOKUP($C12,Intermediate!$C$2:$R$208,16,FALSE)=R12, "", IF(R12="x","+", "-"))
A13: Software Architecture | B13: OU | C13: =_xlfn.CONCAT(B13, " ", A13) -> OU Software Architecture | D13: X | E13: X | T13: =IF(VLOOKUP($C13,Intermediate!$C$2:$R$208,2,FALSE)=D13, "", IF(D13="x","+", "-")) | U13: =IF(VLOOKUP($C13,Intermediate!$C$2:$R$208,3,FALSE)=E13, "", IF(E13="x","+", "-")) | V13: =IF(VLOOKUP($C13,Intermediate!$C$2:$R$208,4,FALSE)=F13, "", IF(F13="x","+", "-")) | W13: =IF(VLOOKUP($C13,Intermediate!$C$2:$R$208,5,FALSE)=G13, "", IF(G13="x","+", "-")) | X13: =IF(VLOOKUP($C13,Intermediate!$C$2:$R$208,6,FALSE)=H13, "", IF(H13="x","+", "-")) | Y13: =IF(VLOOKUP($C13,Intermediate!$C$2:$R$208,7,FALSE)=I13, "", IF(I13="x","+", "-")) | Z13: =IF(VLOOKUP($C13,Intermediate!$C$2:$R$208,8,FALSE)=J13, "", IF(J13="x","+", "-")) | AA13: =IF(VLOOKUP($C13,Intermediate!$C$2:$R$208,9,FALSE)=K13, "", IF(K13="x","+", "-")) | AB13: =IF(VLOOKUP($C13,Intermediate!$C$2:$R$208,10,FALSE)=L13, "", IF(L13="x","+", "-")) | AC13: =IF(VLOOKUP($C13,Intermediate!$C$2:$R$208,11,FALSE)=M13, "", IF(M13="x","+", "-")) | AD13: =IF(VLOOKUP($C13,Intermediate!$C$2:$R$208,12,FALSE)=N13, "", IF(N13="x","+", "-")) | AE13: =IF(VLOOKUP($C13,Intermediate!$C$2:$R$208,13,FALSE)=O13, "", IF(O13="x","+", "-")) | AF13: =IF(VLOOKUP($C13,Intermediate!$C$2:$R$208,14,FALSE)=P13, "", IF(P13="x","+", "-")) | AG13: =IF(VLOOKUP($C13,Intermediate!$C$2:$R$208,15,FALSE)=Q13, "", IF(Q13="x","+", "-")) | AH13: =IF(VLOOKUP($C13,Intermediate!$C$2:$R$208,16,FALSE)=R13, "", IF(R13="x","+", "-"))
A14: Software quality management | B14: OU | C14: =_xlfn.CONCAT(B14, " ", A14) -> OU Software quality management | G14: X | J14: X | M14: X | T14: =IF(VLOOKUP($C14,Intermediate!$C$2:$R$208,2,FALSE)=D14, "", IF(D14="x","+", "-")) | U14: =IF(VLOOKUP($C14,Intermediate!$C$2:$R$208,3,FALSE)=E14, "", IF(E14="x","+", "-")) | V14: =IF(VLOOKUP($C14,Intermediate!$C$2:$R$208,4,FALSE)=F14, "", IF(F14="x","+", "-")) | W14: =IF(VLOOKUP($C14,Intermediate!$C$2:$R$208,5,FALSE)=G14, "", IF(G14="x","+", "-")) | X14: =IF(VLOOKUP($C14,Intermediate!$C$2:$R$208,6,FALSE)=H14, "", IF(H14="x","+", "-")) | Y14: =IF(VLOOKUP($C14,Intermediate!$C$2:$R$208,7,FALSE)=I14, "", IF(I14="x","+", "-")) | Z14: =IF(VLOOKUP($C14,Intermediate!$C$2:$R$208,8,FALSE)=J14, "", IF(J14="x","+", "-")) | AA14: =IF(VLOOKUP($C14,Intermediate!$C$2:$R$208,9,FALSE)=K14, "", IF(K14="x","+", "-")) | AB14: =IF(VLOOKUP($C14,Intermediate!$C$2:$R$208,10,FALSE)=L14, "", IF(L14="x","+", "-")) | AC14: =IF(VLOOKUP($C14,Intermediate!$C$2:$R$208,11,FALSE)=M14, "", IF(M14="x","+", "-")) | AD14: =IF(VLOOKUP($C14,Intermediate!$C$2:$R$208,12,FALSE)=N14, "", IF(N14="x","+", "-")) | AE14: =IF(VLOOKUP($C14,Intermediate!$C$2:$R$208,13,FALSE)=O14, "", IF(O14="x","+", "-")) | AF14: =IF(VLOOKUP($C14,Intermediate!$C$2:$R$208,14,FALSE)=P14, "", IF(P14="x","+", "-")) | AG14: =IF(VLOOKUP($C14,Intermediate!$C$2:$R$208,15,FALSE)=Q14, "", IF(Q14="x","+", "-")) | AH14: =IF(VLOOKUP($C14,Intermediate!$C$2:$R$208,16,FALSE)=R14, "", IF(R14="x","+", "-"))
A15: Software security | B15: OU | C15: =_xlfn.CONCAT(B15, " ", A15) -> OU Software security | O15: X | T15: =IF(VLOOKUP($C15,Intermediate!$C$2:$R$208,2,FALSE)=D15, "", IF(D15="x","+", "-")) | U15: =IF(VLOOKUP($C15,Intermediate!$C$2:$R$208,3,FALSE)=E15, "", IF(E15="x","+", "-")) | V15: =IF(VLOOKUP($C15,Intermediate!$C$2:$R$208,4,FALSE)=F15, "", IF(F15="x","+", "-")) | W15: =IF(VLOOKUP($C15,Intermediate!$C$2:$R$208,5,FALSE)=G15, "", IF(G15="x","+", "-")) | X15: =IF(VLOOKUP($C15,Intermediate!$C$2:$R$208,6,FALSE)=H15, "", IF(H15="x","+", "-")) | Y15: =IF(VLOOKUP($C15,Intermediate!$C$2:$R$208,7,FALSE)=I15, "", IF(I15="x","+", "-")) | Z15: =IF(VLOOKUP($C15,Intermediate!$C$2:$R$208,8,FALSE)=J15, "", IF(J15="x","+", "-")) | AA15: =IF(VLOOKUP($C15,Intermediate!$C$2:$R$208,9,FALSE)=K15, "", IF(K15="x","+", "-")) | AB15: =IF(VLOOKUP($C15,Intermediate!$C$2:$R$208,10,FALSE)=L15, "", IF(L15="x","+", "-")) | AC15: =IF(VLOOKUP($C15,Intermediate!$C$2:$R$208,11,FALSE)=M15, "", IF(M15="x","+", "-")) | AD15: =IF(VLOOKUP($C15,Intermediate!$C$2:$R$208,12,FALSE)=N15, "", IF(N15="x","+", "-")) | AE15: =IF(VLOOKUP($C15,Intermediate!$C$2:$R$208,13,FALSE)=O15, "", IF(O15="x","+", "-")) | AF15: =IF(VLOOKUP($C15,Intermediate!$C$2:$R$208,14,FALSE)=P15, "", IF(P15="x","+", "-")) | AG15: =IF(VLOOKUP($C15,Intermediate!$C$2:$R$208,15,FALSE)=Q15, "", IF(Q15="x","+", "-")) | AH15: =IF(VLOOKUP($C15,Intermediate!$C$2:$R$208,16,FALSE)=R15, "", IF(R15="x","+", "-"))
A16: System verification and testing | B16: OU | C16: =_xlfn.CONCAT(B16, " ", A16) -> OU System verification and testing | H16: X | Q16: X | T16: =IF(VLOOKUP($C16,Intermediate!$C$2:$R$208,2,FALSE)=D16, "", IF(D16="x","+", "-")) | U16: =IF(VLOOKUP($C16,Intermediate!$C$2:$R$208,3,FALSE)=E16, "", IF(E16="x","+", "-")) | V16: =IF(VLOOKUP($C16,Intermediate!$C$2:$R$208,4,FALSE)=F16, "", IF(F16="x","+", "-")) | W16: =IF(VLOOKUP($C16,Intermediate!$C$2:$R$208,5,FALSE)=G16, "", IF(G16="x","+", "-")) | X16: =IF(VLOOKUP($C16,Intermediate!$C$2:$R$208,6,FALSE)=H16, "", IF(H16="x","+", "-")) | Y16: =IF(VLOOKUP($C16,Intermediate!$C$2:$R$208,7,FALSE)=I16, "", IF(I16="x","+", "-")) | Z16: =IF(VLOOKUP($C16,Intermediate!$C$2:$R$208,8,FALSE)=J16, "", IF(J16="x","+", "-")) | AA16: =IF(VLOOKUP($C16,Intermediate!$C$2:$R$208,9,FALSE)=K16, "", IF(K16="x","+", "-")) | AB16: =IF(VLOOKUP($C16,Intermediate!$C$2:$R$208,10,FALSE)=L16, "", IF(L16="x","+", "-")) | AC16: =IF(VLOOKUP($C16,Intermediate!$C$2:$R$208,11,FALSE)=M16, "", IF(M16="x","+", "-")) | AD16: =IF(VLOOKUP($C16,Intermediate!$C$2:$R$208,12,FALSE)=N16, "", IF(N16="x","+", "-")) | AE16: =IF(VLOOKUP($C16,Intermediate!$C$2:$R$208,13,FALSE)=O16, "", IF(O16="x","+", "-")) | AF16: =IF(VLOOKUP($C16,Intermediate!$C$2:$R$208,14,FALSE)=P16, "", IF(P16="x","+", "-")) | AG16: =IF(VLOOKUP($C16,Intermediate!$C$2:$R$208,15,FALSE)=Q16, "", IF(Q16="x","+", "-")) | AH16: =IF(VLOOKUP($C16,Intermediate!$C$2:$R$208,16,FALSE)=R16, "", IF(R16="x","+", "-"))
A17: Functional Programming | B17: RU | C17: =_xlfn.CONCAT(B17, " ", A17) -> RU Functional Programming | G17: X | N17: X | T17: =IF(VLOOKUP($C17,Intermediate!$C$2:$R$208,2,FALSE)=D17, "", IF(D17="x","+", "-")) | U17: =IF(VLOOKUP($C17,Intermediate!$C$2:$R$208,3,FALSE)=E17, "", IF(E17="x","+", "-")) | V17: =IF(VLOOKUP($C17,Intermediate!$C$2:$R$208,4,FALSE)=F17, "", IF(F17="x","+", "-")) | W17: =IF(VLOOKUP($C17,Intermediate!$C$2:$R$208,5,FALSE)=G17, "", IF(G17="x","+", "-")) | X17: =IF(VLOOKUP($C17,Intermediate!$C$2:$R$208,6,FALSE)=H17, "", IF(H17="x","+", "-")) | Y17: =IF(VLOOKUP($C17,Intermediate!$C$2:$R$208,7,FALSE)=I17, "", IF(I17="x","+", "-")) | Z17: =IF(VLOOKUP($C17,Intermediate!$C$2:$R$208,8,FALSE)=J17, "", IF(J17="x","+", "-")) | AA17: =IF(VLOOKUP($C17,Intermediate!$C$2:$R$208,9,FALSE)=K17, "", IF(K17="x","+", "-")) | AB17: =IF(VLOOKUP($C17,Intermediate!$C$2:$R$208,10,FALSE)=L17, "", IF(L17="x","+", "-")) | AC17: =IF(VLOOKUP($C17,Intermediate!$C$2:$R$208,11,FALSE)=M17, "", IF(M17="x","+", "-")) | AD17: =IF(VLOOKUP($C17,Intermediate!$C$2:$R$208,12,FALSE)=N17, "", IF(N17="x","+", "-")) | AE17: =IF(VLOOKUP($C17,Intermediate!$C$2:$R$208,13,FALSE)=O17, "", IF(O17="x","+", "-")) | AF17: =IF(VLOOKUP($C17,Intermediate!$C$2:$R$208,14,FALSE)=P17, "", IF(P17="x","+", "-")) | AG17: =IF(VLOOKUP($C17,Intermediate!$C$2:$R$208,15,FALSE)=Q17, "", IF(Q17="x","+", "-")) | AH17: =IF(VLOOKUP($C17,Intermediate!$C$2:$R$208,16,FALSE)=R17, "", IF(R17="x","+", "-"))
A18: Imperative Programming | B18: RU | C18: =_xlfn.CONCAT(B18, " ", A18) -> RU Imperative Programming | G18: X | T18: =IF(VLOOKUP($C18,Intermediate!$C$2:$R$208,2,FALSE)=D18, "", IF(D18="x","+", "-")) | U18: =IF(VLOOKUP($C18,Intermediate!$C$2:$R$208,3,FALSE)=E18, "", IF(E18="x","+", "-")) | V18: =IF(VLOOKUP($C18,Intermediate!$C$2:$R$208,4,FALSE)=F18, "", IF(F18="x","+", "-")) | W18: =IF(VLOOKUP($C18,Intermediate!$C$2:$R$208,5,FALSE)=G18, "", IF(G18="x","+", "-")) | X18: =IF(VLOOKUP($C18,Intermediate!$C$2:$R$208,6,FALSE)=H18, "", IF(H18="x","+", "-")) | Y18: =IF(VLOOKUP($C18,Intermediate!$C$2:$R$208,7,FALSE)=I18, "", IF(I18="x","+", "-")) | Z18: =IF(VLOOKUP($C18,Intermediate!$C$2:$R$208,8,FALSE)=J18, "", IF(J18="x","+", "-")) | AA18: =IF(VLOOKUP($C18,Intermediate!$C$2:$R$208,9,FALSE)=K18, "", IF(K18="x","+", "-")) | AB18: =IF(VLOOKUP($C18,Intermediate!$C$2:$R$208,10,FALSE)=L18, "", IF(L18="x","+", "-")) | AC18: =IF(VLOOKUP($C18,Intermediate!$C$2:$R$208,11,FALSE)=M18, "", IF(M18="x","+", "-")) | AD18: =IF(VLOOKUP($C18,Intermediate!$C$2:$R$208,12,FALSE)=N18, "", IF(N18="x","+", "-")) | AE18: =IF(VLOOKUP($C18,Intermediate!$C$2:$R$208,13,FALSE)=O18, "", IF(O18="x","+", "-")) | AF18: =IF(VLOOKUP($C18,Intermediate!$C$2:$R$208,14,FALSE)=P18, "", IF(P18="x","+", "-")) | AG18: =IF(VLOOKUP($C18,Intermediate!$C$2:$R$208,15,FALSE)=Q18, "", IF(Q18="x","+", "-")) | AH18: =IF(VLOOKUP($C18,Intermediate!$C$2:$R$208,16,FALSE)=R18, "", IF(R18="x","+", "-"))
A19: Object Oriented Programming | B19: RU | C19: =_xlfn.CONCAT(B19, " ", A19) -> RU Object Oriented Programming | F19: X | G19: X | T19: =IF(VLOOKUP($C19,Intermediate!$C$2:$R$208,2,FALSE)=D19, "", IF(D19="x","+", "-")) | U19: =IF(VLOOKUP($C19,Intermediate!$C$2:$R$208,3,FALSE)=E19, "", IF(E19="x","+", "-")) | V19: =IF(VLOOKUP($C19,Intermediate!$C$2:$R$208,4,FALSE)=F19, "", IF(F19="x","+", "-")) | W19: =IF(VLOOKUP($C19,Intermediate!$C$2:$R$208,5,FALSE)=G19, "", IF(G19="x","+", "-")) | X19: =IF(VLOOKUP($C19,Intermediate!$C$2:$R$208,6,FALSE)=H19, "", IF(H19="x","+", "-")) | Y19: =IF(VLOOKUP($C19,Intermediate!$C$2:$R$208,7,FALSE)=I19, "", IF(I19="x","+", "-")) | Z19: =IF(VLOOKUP($C19,Intermediate!$C$2:$R$208,8,FALSE)=J19, "", IF(J19="x","+", "-")) | AA19: =IF(VLOOKUP($C19,Intermediate!$C$2:$R$208,9,FALSE)=K19, "", IF(K19="x","+", "-")) | AB19: =IF(VLOOKUP($C19,Intermediate!$C$2:$R$208,10,FALSE)=L19, "", IF(L19="x","+", "-")) | AC19: =IF(VLOOKUP($C19,Intermediate!$C$2:$R$208,11,FALSE)=M19, "", IF(M19="x","+", "-")) | AD19: =IF(VLOOKUP($C19,Intermediate!$C$2:$R$208,12,FALSE)=N19, "", IF(N19="x","+", "-")) | AE19: =IF(VLOOKUP($C19,Intermediate!$C$2:$R$208,13,FALSE)=O19, "", IF(O19="x","+", "-")) | AF19: =IF(VLOOKUP($C19,Intermediate!$C$2:$R$208,14,FALSE)=P19, "", IF(P19="x","+", "-")) | AG19: =IF(VLOOKUP($C19,Intermediate!$C$2:$R$208,15,FALSE)=Q19, "", IF(Q19="x","+", "-")) | AH19: =IF(VLOOKUP($C19,Intermediate!$C$2:$R$208,16,FALSE)=R19, "", IF(R19="x","+", "-"))
A20: Requirements Engineering and design | B20: RU | C20: =_xlfn.CONCAT(B20, " ", A20) -> RU Requirements Engineering and design | D20: X | L20: X | T20: =IF(VLOOKUP($C20,Intermediate!$C$2:$R$208,2,FALSE)=D20, "", IF(D20="x","+", "-")) | U20: =IF(VLOOKUP($C20,Intermediate!$C$2:$R$208,3,FALSE)=E20, "", IF(E20="x","+", "-")) | V20: =IF(VLOOKUP($C20,Intermediate!$C$2:$R$208,4,FALSE)=F20, "", IF(F20="x","+", "-")) | W20: =IF(VLOOKUP($C20,Intermediate!$C$2:$R$208,5,FALSE)=G20, "", IF(G20="x","+", "-")) | X20: =IF(VLOOKUP($C20,Intermediate!$C$2:$R$208,6,FALSE)=H20, "", IF(H20="x","+", "-")) | Y20: =IF(VLOOKUP($C20,Intermediate!$C$2:$R$208,7,FALSE)=I20, "", IF(I20="x","+", "-")) | Z20: =IF(VLOOKUP($C20,Intermediate!$C$2:$R$208,8,FALSE)=J20, "", IF(J20="x","+", "-")) | AA20: =IF(VLOOKUP($C20,Intermediate!$C$2:$R$208,9,FALSE)=K20, "", IF(K20="x","+", "-")) | AB20: =IF(VLOOKUP($C20,Intermediate!$C$2:$R$208,10,FALSE)=L20, "", IF(L20="x","+", "-")) | AC20: =IF(VLOOKUP($C20,Intermediate!$C$2:$R$208,11,FALSE)=M20, "", IF(M20="x","+", "-")) | AD20: =IF(VLOOKUP($C20,Intermediate!$C$2:$R$208,12,FALSE)=N20, "", IF(N20="x","+", "-")) | AE20: =IF(VLOOKUP($C20,Intermediate!$C$2:$R$208,13,FALSE)=O20, "", IF(O20="x","+", "-")) | AF20: =IF(VLOOKUP($C20,Intermediate!$C$2:$R$208,14,FALSE)=P20, "", IF(P20="x","+", "-")) | AG20: =IF(VLOOKUP($C20,Intermediate!$C$2:$R$208,15,FALSE)=Q20, "", IF(Q20="x","+", "-")) | AH20: =IF(VLOOKUP($C20,Intermediate!$C$2:$R$208,16,FALSE)=R20, "", IF(R20="x","+", "-"))
A21: Research & Development project | B21: RU | C21: =_xlfn.CONCAT(B21, " ", A21) -> RU Research & Development project | T21: =IF(VLOOKUP($C21,Intermediate!$C$2:$R$208,2,FALSE)=D21, "", IF(D21="x","+", "-")) | U21: =IF(VLOOKUP($C21,Intermediate!$C$2:$R$208,3,FALSE)=E21, "", IF(E21="x","+", "-")) | V21: =IF(VLOOKUP($C21,Intermediate!$C$2:$R$208,4,FALSE)=F21, "", IF(F21="x","+", "-")) | W21: =IF(VLOOKUP($C21,Intermediate!$C$2:$R$208,5,FALSE)=G21, "", IF(G21="x","+", "-")) | X21: =IF(VLOOKUP($C21,Intermediate!$C$2:$R$208,6,FALSE)=H21, "", IF(H21="x","+", "-")) | Y21: =IF(VLOOKUP($C21,Intermediate!$C$2:$R$208,7,FALSE)=I21, "", IF(I21="x","+", "-")) | Z21: =IF(VLOOKUP($C21,Intermediate!$C$2:$R$208,8,FALSE)=J21, "", IF(J21="x","+", "-")) | AA21: =IF(VLOOKUP($C21,Intermediate!$C$2:$R$208,9,FALSE)=K21, "", IF(K21="x","+", "-")) | AB21: =IF(VLOOKUP($C21,Intermediate!$C$2:$R$208,10,FALSE)=L21, "", IF(L21="x","+", "-")) | AC21: =IF(VLOOKUP($C21,Intermediate!$C$2:$R$208,11,FALSE)=M21, "", IF(M21="x","+", "-")) | AD21: =IF(VLOOKUP($C21,Intermediate!$C$2:$R$208,12,FALSE)=N21, "", IF(N21="x","+", "-")) | AE21: =IF(VLOOKUP($C21,Intermediate!$C$2:$R$208,13,FALSE)=O21, "", IF(O21="x","+", "-")) | AF21: =IF(VLOOKUP($C21,Intermediate!$C$2:$R$208,14,FALSE)=P21, "", IF(P21="x","+", "-")) | AG21: =IF(VLOOKUP($C21,Intermediate!$C$2:$R$208,15,FALSE)=Q21, "", IF(Q21="x","+", "-")) | AH21: =IF(VLOOKUP($C21,Intermediate!$C$2:$R$208,16,FALSE)=R21, "", IF(R21="x","+", "-"))
A22: Semantics and Rewriting | B22: RU | C22: =_xlfn.CONCAT(B22, " ", A22) -> RU Semantics and Rewriting | R22: X | T22: =IF(VLOOKUP($C22,Intermediate!$C$2:$R$208,2,FALSE)=D22, "", IF(D22="x","+", "-")) | U22: =IF(VLOOKUP($C22,Intermediate!$C$2:$R$208,3,FALSE)=E22, "", IF(E22="x","+", "-")) | V22: =IF(VLOOKUP($C22,Intermediate!$C$2:$R$208,4,FALSE)=F22, "", IF(F22="x","+", "-")) | W22: =IF(VLOOKUP($C22,Intermediate!$C$2:$R$208,5,FALSE)=G22, "", IF(G22="x","+", "-")) | X22: =IF(VLOOKUP($C22,Intermediate!$C$2:$R$208,6,FALSE)=H22, "", IF(H22="x","+", "-")) | Y22: =IF(VLOOKUP($C22,Intermediate!$C$2:$R$208,7,FALSE)=I22, "", IF(I22="x","+", "-")) | Z22: =IF(VLOOKUP($C22,Intermediate!$C$2:$R$208,8,FALSE)=J22, "", IF(J22="x","+", "-")) | AA22: =IF(VLOOKUP($C22,Intermediate!$C$2:$R$208,9,FALSE)=K22, "", IF(K22="x","+", "-")) | AB22: =IF(VLOOKUP($C22,Intermediate!$C$2:$R$208,10,FALSE)=L22, "", IF(L22="x","+", "-")) | AC22: =IF(VLOOKUP($C22,Intermediate!$C$2:$R$208,11,FALSE)=M22, "", IF(M22="x","+", "-")) | AD22: =IF(VLOOKUP($C22,Intermediate!$C$2:$R$208,12,FALSE)=N22, "", IF(N22="x","+", "-")) | AE22: =IF(VLOOKUP($C22,Intermediate!$C$2:$R$208,13,FALSE)=O22, "", IF(O22="x","+", "-")) | AF22: =IF(VLOOKUP($C22,Intermediate!$C$2:$R$208,14,FALSE)=P22, "", IF(P22="x","+", "-")) | AG22: =IF(VLOOKUP($C22,Intermediate!$C$2:$R$208,15,FALSE)=Q22, "", IF(Q22="x","+", "-")) | AH22: =IF(VLOOKUP($C22,Intermediate!$C$2:$R$208,16,FALSE)=R22, "", IF(R22="x","+", "-"))
A23: Software Engineering | B23: RU | C23: =_xlfn.CONCAT(B23, " ", A23) -> RU Software Engineering | T23: =IF(VLOOKUP($C23,Intermediate!$C$2:$R$208,2,FALSE)=D23, "", IF(D23="x","+", "-")) | U23: =IF(VLOOKUP($C23,Intermediate!$C$2:$R$208,3,FALSE)=E23, "", IF(E23="x","+", "-")) | V23: =IF(VLOOKUP($C23,Intermediate!$C$2:$R$208,4,FALSE)=F23, "", IF(F23="x","+", "-")) | W23: =IF(VLOOKUP($C23,Intermediate!$C$2:$R$208,5,FALSE)=G23, "", IF(G23="x","+", "-")) | X23: =IF(VLOOKUP($C23,Intermediate!$C$2:$R$208,6,FALSE)=H23, "", IF(H23="x","+", "-")) | Y23: =IF(VLOOKUP($C23,Intermediate!$C$2:$R$208,7,FALSE)=I23, "", IF(I23="x","+", "-")) | Z23: =IF(VLOOKUP($C23,Intermediate!$C$2:$R$208,8,FALSE)=J23, "", IF(J23="x","+", "-")) | AA23: =IF(VLOOKUP($C23,Intermediate!$C$2:$R$208,9,FALSE)=K23, "", IF(K23="x","+", "-")) | AB23: =IF(VLOOKUP($C23,Intermediate!$C$2:$R$208,10,FALSE)=L23, "", IF(L23="x","+", "-")) | AC23: =IF(VLOOKUP($C23,Intermediate!$C$2:$R$208,11,FALSE)=M23, "", IF(M23="x","+", "-")) | AD23: =IF(VLOOKUP($C23,Intermediate!$C$2:$R$208,12,FALSE)=N23, "", IF(N23="x","+", "-")) | AE23: =IF(VLOOKUP($C23,Intermediate!$C$2:$R$208,13,FALSE)=O23, "", IF(O23="x","+", "-")) | AF23: =IF(VLOOKUP($C23,Intermediate!$C$2:$R$208,14,FALSE)=P23, "", IF(P23="x","+", "-")) | AG23: =IF(VLOOKUP($C23,Intermediate!$C$2:$R$208,15,FALSE)=Q23, "", IF(Q23="x","+", "-")) | AH23: =IF(VLOOKUP($C23,Intermediate!$C$2:$R$208,16,FALSE)=R23, "", IF(R23="x","+", "-"))
A24: Software Verification | B24: RU | C24: =_xlfn.CONCAT(B24, " ", A24) -> RU Software Verification | H24: X | N24: X | Q24: X | T24: =IF(VLOOKUP($C24,Intermediate!$C$2:$R$208,2,FALSE)=D24, "", IF(D24="x","+", "-")) | U24: =IF(VLOOKUP($C24,Intermediate!$C$2:$R$208,3,FALSE)=E24, "", IF(E24="x","+", "-")) | V24: =IF(VLOOKUP($C24,Intermediate!$C$2:$R$208,4,FALSE)=F24, "", IF(F24="x","+", "-")) | W24: =IF(VLOOKUP($C24,Intermediate!$C$2:$R$208,5,FALSE)=G24, "", IF(G24="x","+", "-")) | X24: =IF(VLOOKUP($C24,Intermediate!$C$2:$R$208,6,FALSE)=H24, "", IF(H24="x","+", "-")) | Y24: =IF(VLOOKUP($C24,Intermediate!$C$2:$R$208,7,FALSE)=I24, "", IF(I24="x","+", "-")) | Z24: =IF(VLOOKUP($C24,Intermediate!$C$2:$R$208,8,FALSE)=J24, "", IF(J24="x","+", "-")) | AA24: =IF(VLOOKUP($C24,Intermediate!$C$2:$R$208,9,FALSE)=K24, "", IF(K24="x","+", "-")) | AB24: =IF(VLOOKUP($C24,Intermediate!$C$2:$R$208,10,FALSE)=L24, "", IF(L24="x","+", "-")) | AC24: =IF(VLOOKUP($C24,Intermediate!$C$2:$R$208,11,FALSE)=M24, "", IF(M24="x","+", "-")) | AD24: =IF(VLOOKUP($C24,Intermediate!$C$2:$R$208,12,FALSE)=N24, "", IF(N24="x","+", "-")) | AE24: =IF(VLOOKUP($C24,Intermediate!$C$2:$R$208,13,FALSE)=O24, "", IF(O24="x","+", "-")) | AF24: =IF(VLOOKUP($C24,Intermediate!$C$2:$R$208,14,FALSE)=P24, "", IF(P24="x","+", "-")) | AG24: =IF(VLOOKUP($C24,Intermediate!$C$2:$R$208,15,FALSE)=Q24, "", IF(Q24="x","+", "-")) | AH24: =IF(VLOOKUP($C24,Intermediate!$C$2:$R$208,16,FALSE)=R24, "", IF(R24="x","+", "-"))
A25: Advanced Programming | B25: RU | C25: =_xlfn.CONCAT(B25, " ", A25) -> RU Advanced Programming | G25: X | R25: X | T25: =IF(VLOOKUP($C25,Intermediate!$C$2:$R$208,2,FALSE)=D25, "", IF(D25="x","+", "-")) | U25: =IF(VLOOKUP($C25,Intermediate!$C$2:$R$208,3,FALSE)=E25, "", IF(E25="x","+", "-")) | V25: =IF(VLOOKUP($C25,Intermediate!$C$2:$R$208,4,FALSE)=F25, "", IF(F25="x","+", "-")) | W25: =IF(VLOOKUP($C25,Intermediate!$C$2:$R$208,5,FALSE)=G25, "", IF(G25="x","+", "-")) | X25: =IF(VLOOKUP($C25,Intermediate!$C$2:$R$208,6,FALSE)=H25, "", IF(H25="x","+", "-")) | Y25: =IF(VLOOKUP($C25,Intermediate!$C$2:$R$208,7,FALSE)=I25, "", IF(I25="x","+", "-")) | Z25: =IF(VLOOKUP($C25,Intermediate!$C$2:$R$208,8,FALSE)=J25, "", IF(J25="x","+", "-")) | AA25: =IF(VLOOKUP($C25,Intermediate!$C$2:$R$208,9,FALSE)=K25, "", IF(K25="x","+", "-")) | AB25: =IF(VLOOKUP($C25,Intermediate!$C$2:$R$208,10,FALSE)=L25, "", IF(L25="x","+", "-")) | AC25: =IF(VLOOKUP($C25,Intermediate!$C$2:$R$208,11,FALSE)=M25, "", IF(M25="x","+", "-")) | AD25: =IF(VLOOKUP($C25,Intermediate!$C$2:$R$208,12,FALSE)=N25, "", IF(N25="x","+", "-")) | AE25: =IF(VLOOKUP($C25,Intermediate!$C$2:$R$208,13,FALSE)=O25, "", IF(O25="x","+", "-")) | AF25: =IF(VLOOKUP($C25,Intermediate!$C$2:$R$208,14,FALSE)=P25, "", IF(P25="x","+", "-")) | AG25: =IF(VLOOKUP($C25,Intermediate!$C$2:$R$208,15,FALSE)=Q25, "", IF(Q25="x","+", "-")) | AH25: =IF(VLOOKUP($C25,Intermediate!$C$2:$R$208,16,FALSE)=R25, "", IF(R25="x","+", "-"))
A26: Compiler construction | B26: RU | C26: =_xlfn.CONCAT(B26, " ", A26) -> RU Compiler construction | R26: X | T26: =IF(VLOOKUP($C26,Intermediate!$C$2:$R$208,2,FALSE)=D26, "", IF(D26="x","+", "-")) | U26: =IF(VLOOKUP($C26,Intermediate!$C$2:$R$208,3,FALSE)=E26, "", IF(E26="x","+", "-")) | V26: =IF(VLOOKUP($C26,Intermediate!$C$2:$R$208,4,FALSE)=F26, "", IF(F26="x","+", "-")) | W26: =IF(VLOOKUP($C26,Intermediate!$C$2:$R$208,5,FALSE)=G26, "", IF(G26="x","+", "-")) | X26: =IF(VLOOKUP($C26,Intermediate!$C$2:$R$208,6,FALSE)=H26, "", IF(H26="x","+", "-")) | Y26: =IF(VLOOKUP($C26,Intermediate!$C$2:$R$208,7,FALSE)=I26, "", IF(I26="x","+", "-")) | Z26: =IF(VLOOKUP($C26,Intermediate!$C$2:$R$208,8,FALSE)=J26, "", IF(J26="x","+", "-")) | AA26: =IF(VLOOKUP($C26,Intermediate!$C$2:$R$208,9,FALSE)=K26, "", IF(K26="x","+", "-")) | AB26: =IF(VLOOKUP($C26,Intermediate!$C$2:$R$208,10,FALSE)=L26, "", IF(L26="x","+", "-")) | AC26: =IF(VLOOKUP($C26,Intermediate!$C$2:$R$208,11,FALSE)=M26, "", IF(M26="x","+", "-")) | AD26: =IF(VLOOKUP($C26,Intermediate!$C$2:$R$208,12,FALSE)=N26, "", IF(N26="x","+", "-")) | AE26: =IF(VLOOKUP($C26,Intermediate!$C$2:$R$208,13,FALSE)=O26, "", IF(O26="x","+", "-")) | AF26: =IF(VLOOKUP($C26,Intermediate!$C$2:$R$208,14,FALSE)=P26, "", IF(P26="x","+", "-")) | AG26: =IF(VLOOKUP($C26,Intermediate!$C$2:$R$208,15,FALSE)=Q26, "", IF(Q26="x","+", "-")) | AH26: =IF(VLOOKUP($C26,Intermediate!$C$2:$R$208,16,FALSE)=R26, "", IF(R26="x","+", "-"))
A27: Model checking | B27: RU | C27: =_xlfn.CONCAT(B27, " ", A27) -> RU Model checking | Q27: X | T27: =IF(VLOOKUP($C27,Intermediate!$C$2:$R$208,2,FALSE)=D27, "", IF(D27="x","+", "-")) | U27: =IF(VLOOKUP($C27,Intermediate!$C$2:$R$208,3,FALSE)=E27, "", IF(E27="x","+", "-")) | V27: =IF(VLOOKUP($C27,Intermediate!$C$2:$R$208,4,FALSE)=F27, "", IF(F27="x","+", "-")) | W27: =IF(VLOOKUP($C27,Intermediate!$C$2:$R$208,5,FALSE)=G27, "", IF(G27="x","+", "-")) | X27: =IF(VLOOKUP($C27,Intermediate!$C$2:$R$208,6,FALSE)=H27, "", IF(H27="x","+", "-")) | Y27: =IF(VLOOKUP($C27,Intermediate!$C$2:$R$208,7,FALSE)=I27, "", IF(I27="x","+", "-")) | Z27: =IF(VLOOKUP($C27,Intermediate!$C$2:$R$208,8,FALSE)=J27, "", IF(J27="x","+", "-")) | AA27: =IF(VLOOKUP($C27,Intermediate!$C$2:$R$208,9,FALSE)=K27, "", IF(K27="x","+", "-")) | AB27: =IF(VLOOKUP($C27,Intermediate!$C$2:$R$208,10,FALSE)=L27, "", IF(L27="x","+", "-")) | AC27: =IF(VLOOKUP($C27,Intermediate!$C$2:$R$208,11,FALSE)=M27, "", IF(M27="x","+", "-")) | AD27: =IF(VLOOKUP($C27,Intermediate!$C$2:$R$208,12,FALSE)=N27, "", IF(N27="x","+", "-")) | AE27: =IF(VLOOKUP($C27,Intermediate!$C$2:$R$208,13,FALSE)=O27, "", IF(O27="x","+", "-")) | AF27: =IF(VLOOKUP($C27,Intermediate!$C$2:$R$208,14,FALSE)=P27, "", IF(P27="x","+", "-")) | AG27: =IF(VLOOKUP($C27,Intermediate!$C$2:$R$208,15,FALSE)=Q27, "", IF(Q27="x","+", "-")) | AH27: =IF(VLOOKUP($C27,Intermediate!$C$2:$R$208,16,FALSE)=R27, "", IF(R27="x","+", "-"))
A28: Program verification with types and logic | B28: RU | C28: =_xlfn.CONCAT(B28, " ", A28) -> RU Program verification with types and logic | Q28: X | R28: X | T28: =IF(VLOOKUP($C28,Intermediate!$C$2:$R$208,2,FALSE)=D28, "", IF(D28="x","+", "-")) | U28: =IF(VLOOKUP($C28,Intermediate!$C$2:$R$208,3,FALSE)=E28, "", IF(E28="x","+", "-")) | V28: =IF(VLOOKUP($C28,Intermediate!$C$2:$R$208,4,FALSE)=F28, "", IF(F28="x","+", "-")) | W28: =IF(VLOOKUP($C28,Intermediate!$C$2:$R$208,5,FALSE)=G28, "", IF(G28="x","+", "-")) | X28: =IF(VLOOKUP($C28,Intermediate!$C$2:$R$208,6,FALSE)=H28, "", IF(H28="x","+", "-")) | Y28: =IF(VLOOKUP($C28,Intermediate!$C$2:$R$208,7,FALSE)=I28, "", IF(I28="x","+", "-")) | Z28: =IF(VLOOKUP($C28,Intermediate!$C$2:$R$208,8,FALSE)=J28, "", IF(J28="x","+", "-")) | AA28: =IF(VLOOKUP($C28,Intermediate!$C$2:$R$208,9,FALSE)=K28, "", IF(K28="x","+", "-")) | AB28: =IF(VLOOKUP($C28,Intermediate!$C$2:$R$208,10,FALSE)=L28, "", IF(L28="x","+", "-")) | AC28: =IF(VLOOKUP($C28,Intermediate!$C$2:$R$208,11,FALSE)=M28, "", IF(M28="x","+", "-")) | AD28: =IF(VLOOKUP($C28,Intermediate!$C$2:$R$208,12,FALSE)=N28, "", IF(N28="x","+", "-")) | AE28: =IF(VLOOKUP($C28,Intermediate!$C$2:$R$208,13,FALSE)=O28, "", IF(O28="x","+", "-")) | AF28: =IF(VLOOKUP($C28,Intermediate!$C$2:$R$208,14,FALSE)=P28, "", IF(P28="x","+", "-")) | AG28: =IF(VLOOKUP($C28,Intermediate!$C$2:$R$208,15,FALSE)=Q28, "", IF(Q28="x","+", "-")) | AH28: =IF(VLOOKUP($C28,Intermediate!$C$2:$R$208,16,FALSE)=R28, "", IF(R28="x","+", "-"))
A29: Research Seminar Software Science | B29: RU | C29: =_xlfn.CONCAT(B29, " ", A29) -> RU Research Seminar Software Science | T29: =IF(VLOOKUP($C29,Intermediate!$C$2:$R$208,2,FALSE)=D29, "", IF(D29="x","+", "-")) | U29: =IF(VLOOKUP($C29,Intermediate!$C$2:$R$208,3,FALSE)=E29, "", IF(E29="x","+", "-")) | V29: =IF(VLOOKUP($C29,Intermediate!$C$2:$R$208,4,FALSE)=F29, "", IF(F29="x","+", "-")) | W29: =IF(VLOOKUP($C29,Intermediate!$C$2:$R$208,5,FALSE)=G29, "", IF(G29="x","+", "-")) | X29: =IF(VLOOKUP($C29,Intermediate!$C$2:$R$208,6,FALSE)=H29, "", IF(H29="x","+", "-")) | Y29: =IF(VLOOKUP($C29,Intermediate!$C$2:$R$208,7,FALSE)=I29, "", IF(I29="x","+", "-")) | Z29: =IF(VLOOKUP($C29,Intermediate!$C$2:$R$208,8,FALSE)=J29, "", IF(J29="x","+", "-")) | AA29: =IF(VLOOKUP($C29,Intermediate!$C$2:$R$208,9,FALSE)=K29, "", IF(K29="x","+", "-")) | AB29: =IF(VLOOKUP($C29,Intermediate!$C$2:$R$208,10,FALSE)=L29, "", IF(L29="x","+", "-")) | AC29: =IF(VLOOKUP($C29,Intermediate!$C$2:$R$208,11,FALSE)=M29, "", IF(M29="x","+", "-")) | AD29: =IF(VLOOKUP($C29,Intermediate!$C$2:$R$208,12,FALSE)=N29, "", IF(N29="x","+", "-")) | AE29: =IF(VLOOKUP($C29,Intermediate!$C$2:$R$208,13,FALSE)=O29, "", IF(O29="x","+", "-")) | AF29: =IF(VLOOKUP($C29,Intermediate!$C$2:$R$208,14,FALSE)=P29, "", IF(P29="x","+", "-")) | AG29: =IF(VLOOKUP($C29,Intermediate!$C$2:$R$208,15,FALSE)=Q29, "", IF(Q29="x","+", "-")) | AH29: =IF(VLOOKUP($C29,Intermediate!$C$2:$R$208,16,FALSE)=R29, "", IF(R29="x","+", "-"))
A30: Software Development Entrepreneurship | B30: RU | C30: =_xlfn.CONCAT(B30, " ", A30) -> RU Software Development Entrepreneurship | L30: X | M30: X | P30: X | T30: =IF(VLOOKUP($C30,Intermediate!$C$2:$R$208,2,FALSE)=D30, "", IF(D30="x","+", "-")) | U30: =IF(VLOOKUP($C30,Intermediate!$C$2:$R$208,3,FALSE)=E30, "", IF(E30="x","+", "-")) | V30: =IF(VLOOKUP($C30,Intermediate!$C$2:$R$208,4,FALSE)=F30, "", IF(F30="x","+", "-")) | W30: =IF(VLOOKUP($C30,Intermediate!$C$2:$R$208,5,FALSE)=G30, "", IF(G30="x","+", "-")) | X30: =IF(VLOOKUP($C30,Intermediate!$C$2:$R$208,6,FALSE)=H30, "", IF(H30="x","+", "-")) | Y30: =IF(VLOOKUP($C30,Intermediate!$C$2:$R$208,7,FALSE)=I30, "", IF(I30="x","+", "-")) | Z30: =IF(VLOOKUP($C30,Intermediate!$C$2:$R$208,8,FALSE)=J30, "", IF(J30="x","+", "-")) | AA30: =IF(VLOOKUP($C30,Intermediate!$C$2:$R$208,9,FALSE)=K30, "", IF(K30="x","+", "-")) | AB30: =IF(VLOOKUP($C30,Intermediate!$C$2:$R$208,10,FALSE)=L30, "", IF(L30="x","+", "-")) | AC30: =IF(VLOOKUP($C30,Intermediate!$C$2:$R$208,11,FALSE)=M30, "", IF(M30="x","+", "-")) | AD30: =IF(VLOOKUP($C30,Intermediate!$C$2:$R$208,12,FALSE)=N30, "", IF(N30="x","+", "-")) | AE30: =IF(VLOOKUP($C30,Intermediate!$C$2:$R$208,13,FALSE)=O30, "", IF(O30="x","+", "-")) | AF30: =IF(VLOOKUP($C30,Intermediate!$C$2:$R$208,14,FALSE)=P30, "", IF(P30="x","+", "-")) | AG30: =IF(VLOOKUP($C30,Intermediate!$C$2:$R$208,15,FALSE)=Q30, "", IF(Q30="x","+", "-")) | AH30: =IF(VLOOKUP($C30,Intermediate!$C$2:$R$208,16,FALSE)=R30, "", IF(R30="x","+", "-"))
A31: Software Product Lines | B31: RU | C31: =_xlfn.CONCAT(B31, " ", A31) -> RU Software Product Lines | E31: X | I31: X | L31: X | T31: =IF(VLOOKUP($C31,Intermediate!$C$2:$R$208,2,FALSE)=D31, "", IF(D31="x","+", "-")) | U31: =IF(VLOOKUP($C31,Intermediate!$C$2:$R$208,3,FALSE)=E31, "", IF(E31="x","+", "-")) | V31: =IF(VLOOKUP($C31,Intermediate!$C$2:$R$208,4,FALSE)=F31, "", IF(F31="x","+", "-")) | W31: =IF(VLOOKUP($C31,Intermediate!$C$2:$R$208,5,FALSE)=G31, "", IF(G31="x","+", "-")) | X31: =IF(VLOOKUP($C31,Intermediate!$C$2:$R$208,6,FALSE)=H31, "", IF(H31="x","+", "-")) | Y31: =IF(VLOOKUP($C31,Intermediate!$C$2:$R$208,7,FALSE)=I31, "", IF(I31="x","+", "-")) | Z31: =IF(VLOOKUP($C31,Intermediate!$C$2:$R$208,8,FALSE)=J31, "", IF(J31="x","+", "-")) | AA31: =IF(VLOOKUP($C31,Intermediate!$C$2:$R$208,9,FALSE)=K31, "", IF(K31="x","+", "-")) | AB31: =IF(VLOOKUP($C31,Intermediate!$C$2:$R$208,10,FALSE)=L31, "", IF(L31="x","+", "-")) | AC31: =IF(VLOOKUP($C31,Intermediate!$C$2:$R$208,11,FALSE)=M31, "", IF(M31="x","+", "-")) | AD31: =IF(VLOOKUP($C31,Intermediate!$C$2:$R$208,12,FALSE)=N31, "", IF(N31="x","+", "-")) | AE31: =IF(VLOOKUP($C31,Intermediate!$C$2:$R$208,13,FALSE)=O31, "", IF(O31="x","+", "-")) | AF31: =IF(VLOOKUP($C31,Intermediate!$C$2:$R$208,14,FALSE)=P31, "", IF(P31="x","+", "-")) | AG31: =IF(VLOOKUP($C31,Intermediate!$C$2:$R$208,15,FALSE)=Q31, "", IF(Q31="x","+", "-")) | AH31: =IF(VLOOKUP($C31,Intermediate!$C$2:$R$208,16,FALSE)=R31, "", IF(R31="x","+", "-"))
A32: Software Security | B32: RU | C32: =_xlfn.CONCAT(B32, " ", A32) -> RU Software Security | O32: X | T32: =IF(VLOOKUP($C32,Intermediate!$C$2:$R$208,2,FALSE)=D32, "", IF(D32="x","+", "-")) | U32: =IF(VLOOKUP($C32,Intermediate!$C$2:$R$208,3,FALSE)=E32, "", IF(E32="x","+", "-")) | V32: =IF(VLOOKUP($C32,Intermediate!$C$2:$R$208,4,FALSE)=F32, "", IF(F32="x","+", "-")) | W32: =IF(VLOOKUP($C32,Intermediate!$C$2:$R$208,5,FALSE)=G32, "", IF(G32="x","+", "-")) | X32: =IF(VLOOKUP($C32,Intermediate!$C$2:$R$208,6,FALSE)=H32, "", IF(H32="x","+", "-")) | Y32: =IF(VLOOKUP($C32,Intermediate!$C$2:$R$208,7,FALSE)=I32, "", IF(I32="x","+", "-")) | Z32: =IF(VLOOKUP($C32,Intermediate!$C$2:$R$208,8,FALSE)=J32, "", IF(J32="x","+", "-")) | AA32: =IF(VLOOKUP($C32,Intermediate!$C$2:$R$208,9,FALSE)=K32, "", IF(K32="x","+", "-")) | AB32: =IF(VLOOKUP($C32,Intermediate!$C$2:$R$208,10,FALSE)=L32, "", IF(L32="x","+", "-")) | AC32: =IF(VLOOKUP($C32,Intermediate!$C$2:$R$208,11,FALSE)=M32, "", IF(M32="x","+", "-")) | AD32: =IF(VLOOKUP($C32,Intermediate!$C$2:$R$208,12,FALSE)=N32, "", IF(N32="x","+", "-")) | AE32: =IF(VLOOKUP($C32,Intermediate!$C$2:$R$208,13,FALSE)=O32, "", IF(O32="x","+", "-")) | AF32: =IF(VLOOKUP($C32,Intermediate!$C$2:$R$208,14,FALSE)=P32, "", IF(P32="x","+", "-")) | AG32: =IF(VLOOKUP($C32,Intermediate!$C$2:$R$208,15,FALSE)=Q32, "", IF(Q32="x","+", "-")) | AH32: =IF(VLOOKUP($C32,Intermediate!$C$2:$R$208,16,FALSE)=R32, "", IF(R32="x","+", "-"))
A33: Systems Development Management | B33: RU | C33: =_xlfn.CONCAT(B33, " ", A33) -> RU Systems Development Management | I33: X | L33: X | M33: X | T33: =IF(VLOOKUP($C33,Intermediate!$C$2:$R$208,2,FALSE)=D33, "", IF(D33="x","+", "-")) | U33: =IF(VLOOKUP($C33,Intermediate!$C$2:$R$208,3,FALSE)=E33, "", IF(E33="x","+", "-")) | V33: =IF(VLOOKUP($C33,Intermediate!$C$2:$R$208,4,FALSE)=F33, "", IF(F33="x","+", "-")) | W33: =IF(VLOOKUP($C33,Intermediate!$C$2:$R$208,5,FALSE)=G33, "", IF(G33="x","+", "-")) | X33: =IF(VLOOKUP($C33,Intermediate!$C$2:$R$208,6,FALSE)=H33, "", IF(H33="x","+", "-")) | Y33: =IF(VLOOKUP($C33,Intermediate!$C$2:$R$208,7,FALSE)=I33, "", IF(I33="x","+", "-")) | Z33: =IF(VLOOKUP($C33,Intermediate!$C$2:$R$208,8,FALSE)=J33, "", IF(J33="x","+", "-")) | AA33: =IF(VLOOKUP($C33,Intermediate!$C$2:$R$208,9,FALSE)=K33, "", IF(K33="x","+", "-")) | AB33: =IF(VLOOKUP($C33,Intermediate!$C$2:$R$208,10,FALSE)=L33, "", IF(L33="x","+", "-")) | AC33: =IF(VLOOKUP($C33,Intermediate!$C$2:$R$208,11,FALSE)=M33, "", IF(M33="x","+", "-")) | AD33: =IF(VLOOKUP($C33,Intermediate!$C$2:$R$208,12,FALSE)=N33, "", IF(N33="x","+", "-")) | AE33: =IF(VLOOKUP($C33,Intermediate!$C$2:$R$208,13,FALSE)=O33, "", IF(O33="x","+", "-")) | AF33: =IF(VLOOKUP($C33,Intermediate!$C$2:$R$208,14,FALSE)=P33, "", IF(P33="x","+", "-")) | AG33: =IF(VLOOKUP($C33,Intermediate!$C$2:$R$208,15,FALSE)=Q33, "", IF(Q33="x","+", "-")) | AH33: =IF(VLOOKUP($C33,Intermediate!$C$2:$R$208,16,FALSE)=R33, "", IF(R33="x","+", "-"))
A34: Testing Techniques | B34: RU | C34: =_xlfn.CONCAT(B34, " ", A34) -> RU Testing Techniques | H34: X | M34: X | N34: X | T34: =IF(VLOOKUP($C34,Intermediate!$C$2:$R$208,2,FALSE)=D34, "", IF(D34="x","+", "-")) | U34: =IF(VLOOKUP($C34,Intermediate!$C$2:$R$208,3,FALSE)=E34, "", IF(E34="x","+", "-")) | V34: =IF(VLOOKUP($C34,Intermediate!$C$2:$R$208,4,FALSE)=F34, "", IF(F34="x","+", "-")) | W34: =IF(VLOOKUP($C34,Intermediate!$C$2:$R$208,5,FALSE)=G34, "", IF(G34="x","+", "-")) | X34: =IF(VLOOKUP($C34,Intermediate!$C$2:$R$208,6,FALSE)=H34, "", IF(H34="x","+", "-")) | Y34: =IF(VLOOKUP($C34,Intermediate!$C$2:$R$208,7,FALSE)=I34, "", IF(I34="x","+", "-")) | Z34: =IF(VLOOKUP($C34,Intermediate!$C$2:$R$208,8,FALSE)=J34, "", IF(J34="x","+", "-")) | AA34: =IF(VLOOKUP($C34,Intermediate!$C$2:$R$208,9,FALSE)=K34, "", IF(K34="x","+", "-")) | AB34: =IF(VLOOKUP($C34,Intermediate!$C$2:$R$208,10,FALSE)=L34, "", IF(L34="x","+", "-")) | AC34: =IF(VLOOKUP($C34,Intermediate!$C$2:$R$208,11,FALSE)=M34, "", IF(M34="x","+", "-")) | AD34: =IF(VLOOKUP($C34,Intermediate!$C$2:$R$208,12,FALSE)=N34, "", IF(N34="x","+", "-")) | AE34: =IF(VLOOKUP($C34,Intermediate!$C$2:$R$208,13,FALSE)=O34, "", IF(O34="x","+", "-")) | AF34: =IF(VLOOKUP($C34,Intermediate!$C$2:$R$208,14,FALSE)=P34, "", IF(P34="x","+", "-")) | AG34: =IF(VLOOKUP($C34,Intermediate!$C$2:$R$208,15,FALSE)=Q34, "", IF(Q34="x","+", "-")) | AH34: =IF(VLOOKUP($C34,Intermediate!$C$2:$R$208,16,FALSE)=R34, "", IF(R34="x","+", "-"))
A35: Type Theory and Coq | B35: RU | C35: =_xlfn.CONCAT(B35, " ", A35) -> RU Type Theory and Coq | Q35: X | R35: X | T35: =IF(VLOOKUP($C35,Intermediate!$C$2:$R$208,2,FALSE)=D35, "", IF(D35="x","+", "-")) | U35: =IF(VLOOKUP($C35,Intermediate!$C$2:$R$208,3,FALSE)=E35, "", IF(E35="x","+", "-")) | V35: =IF(VLOOKUP($C35,Intermediate!$C$2:$R$208,4,FALSE)=F35, "", IF(F35="x","+", "-")) | W35: =IF(VLOOKUP($C35,Intermediate!$C$2:$R$208,5,FALSE)=G35, "", IF(G35="x","+", "-")) | X35: =IF(VLOOKUP($C35,Intermediate!$C$2:$R$208,6,FALSE)=H35, "", IF(H35="x","+", "-")) | Y35: =IF(VLOOKUP($C35,Intermediate!$C$2:$R$208,7,FALSE)=I35, "", IF(I35="x","+", "-")) | Z35: =IF(VLOOKUP($C35,Intermediate!$C$2:$R$208,8,FALSE)=J35, "", IF(J35="x","+", "-")) | AA35: =IF(VLOOKUP($C35,Intermediate!$C$2:$R$208,9,FALSE)=K35, "", IF(K35="x","+", "-")) | AB35: =IF(VLOOKUP($C35,Intermediate!$C$2:$R$208,10,FALSE)=L35, "", IF(L35="x","+", "-")) | AC35: =IF(VLOOKUP($C35,Intermediate!$C$2:$R$208,11,FALSE)=M35, "", IF(M35="x","+", "-")) | AD35: =IF(VLOOKUP($C35,Intermediate!$C$2:$R$208,12,FALSE)=N35, "", IF(N35="x","+", "-")) | AE35: =IF(VLOOKUP($C35,Intermediate!$C$2:$R$208,13,FALSE)=O35, "", IF(O35="x","+", "-")) | AF35: =IF(VLOOKUP($C35,Intermediate!$C$2:$R$208,14,FALSE)=P35, "", IF(P35="x","+", "-")) | AG35: =IF(VLOOKUP($C35,Intermediate!$C$2:$R$208,15,FALSE)=Q35, "", IF(Q35="x","+", "-")) | AH35: =IF(VLOOKUP($C35,Intermediate!$C$2:$R$208,16,FALSE)=R35, "", IF(R35="x","+", "-"))
A36: Advanced Object Oriented Programming | B36: RUG | C36: =_xlfn.CONCAT(B36, " ", A36) -> RUG Advanced Object Oriented Programming | F36: X | G36: X | K36: X | M36: X | T36: =IF(VLOOKUP($C36,Intermediate!$C$2:$R$208,2,FALSE)=D36, "", IF(D36="x","+", "-")) | U36: =IF(VLOOKUP($C36,Intermediate!$C$2:$R$208,3,FALSE)=E36, "", IF(E36="x","+", "-")) | V36: =IF(VLOOKUP($C36,Intermediate!$C$2:$R$208,4,FALSE)=F36, "", IF(F36="x","+", "-")) | W36: =IF(VLOOKUP($C36,Intermediate!$C$2:$R$208,5,FALSE)=G36, "", IF(G36="x","+", "-")) | X36: =IF(VLOOKUP($C36,Intermediate!$C$2:$R$208,6,FALSE)=H36, "", IF(H36="x","+", "-")) | Y36: =IF(VLOOKUP($C36,Intermediate!$C$2:$R$208,7,FALSE)=I36, "", IF(I36="x","+", "-")) | Z36: =IF(VLOOKUP($C36,Intermediate!$C$2:$R$208,8,FALSE)=J36, "", IF(J36="x","+", "-")) | AA36: =IF(VLOOKUP($C36,Intermediate!$C$2:$R$208,9,FALSE)=K36, "", IF(K36="x","+", "-")) | AB36: =IF(VLOOKUP($C36,Intermediate!$C$2:$R$208,10,FALSE)=L36, "", IF(L36="x","+", "-")) | AC36: =IF(VLOOKUP($C36,Intermediate!$C$2:$R$208,11,FALSE)=M36, "", IF(M36="x","+", "-")) | AD36: =IF(VLOOKUP($C36,Intermediate!$C$2:$R$208,12,FALSE)=N36, "", IF(N36="x","+", "-")) | AE36: =IF(VLOOKUP($C36,Intermediate!$C$2:$R$208,13,FALSE)=O36, "", IF(O36="x","+", "-")) | AF36: =IF(VLOOKUP($C36,Intermediate!$C$2:$R$208,14,FALSE)=P36, "", IF(P36="x","+", "-")) | AG36: =IF(VLOOKUP($C36,Intermediate!$C$2:$R$208,15,FALSE)=Q36, "", IF(Q36="x","+", "-")) | AH36: =IF(VLOOKUP($C36,Intermediate!$C$2:$R$208,16,FALSE)=R36, "", IF(R36="x","+", "-"))
A37: Advanced programming in C++ | B37: RUG | C37: =_xlfn.CONCAT(B37, " ", A37) -> RUG Advanced programming in C++ | G37: X | T37: =IF(VLOOKUP($C37,Intermediate!$C$2:$R$208,2,FALSE)=D37, "", IF(D37="x","+", "-")) | U37: =IF(VLOOKUP($C37,Intermediate!$C$2:$R$208,3,FALSE)=E37, "", IF(E37="x","+", "-")) | V37: =IF(VLOOKUP($C37,Intermediate!$C$2:$R$208,4,FALSE)=F37, "", IF(F37="x","+", "-")) | W37: =IF(VLOOKUP($C37,Intermediate!$C$2:$R$208,5,FALSE)=G37, "", IF(G37="x","+", "-")) | X37: =IF(VLOOKUP($C37,Intermediate!$C$2:$R$208,6,FALSE)=H37, "", IF(H37="x","+", "-")) | Y37: =IF(VLOOKUP($C37,Intermediate!$C$2:$R$208,7,FALSE)=I37, "", IF(I37="x","+", "-")) | Z37: =IF(VLOOKUP($C37,Intermediate!$C$2:$R$208,8,FALSE)=J37, "", IF(J37="x","+", "-")) | AA37: =IF(VLOOKUP($C37,Intermediate!$C$2:$R$208,9,FALSE)=K37, "", IF(K37="x","+", "-")) | AB37: =IF(VLOOKUP($C37,Intermediate!$C$2:$R$208,10,FALSE)=L37, "", IF(L37="x","+", "-")) | AC37: =IF(VLOOKUP($C37,Intermediate!$C$2:$R$208,11,FALSE)=M37, "", IF(M37="x","+", "-")) | AD37: =IF(VLOOKUP($C37,Intermediate!$C$2:$R$208,12,FALSE)=N37, "", IF(N37="x","+", "-")) | AE37: =IF(VLOOKUP($C37,Intermediate!$C$2:$R$208,13,FALSE)=O37, "", IF(O37="x","+", "-")) | AF37: =IF(VLOOKUP($C37,Intermediate!$C$2:$R$208,14,FALSE)=P37, "", IF(P37="x","+", "-")) | AG37: =IF(VLOOKUP($C37,Intermediate!$C$2:$R$208,15,FALSE)=Q37, "", IF(Q37="x","+", "-")) | AH37: =IF(VLOOKUP($C37,Intermediate!$C$2:$R$208,16,FALSE)=R37, "", IF(R37="x","+", "-"))
A38: Compiler Construction | B38: RUG | C38: =_xlfn.CONCAT(B38, " ", A38) -> RUG Compiler Construction | R38: X | T38: =IF(VLOOKUP($C38,Intermediate!$C$2:$R$208,2,FALSE)=D38, "", IF(D38="x","+", "-")) | U38: =IF(VLOOKUP($C38,Intermediate!$C$2:$R$208,3,FALSE)=E38, "", IF(E38="x","+", "-")) | V38: =IF(VLOOKUP($C38,Intermediate!$C$2:$R$208,4,FALSE)=F38, "", IF(F38="x","+", "-")) | W38: =IF(VLOOKUP($C38,Intermediate!$C$2:$R$208,5,FALSE)=G38, "", IF(G38="x","+", "-")) | X38: =IF(VLOOKUP($C38,Intermediate!$C$2:$R$208,6,FALSE)=H38, "", IF(H38="x","+", "-")) | Y38: =IF(VLOOKUP($C38,Intermediate!$C$2:$R$208,7,FALSE)=I38, "", IF(I38="x","+", "-")) | Z38: =IF(VLOOKUP($C38,Intermediate!$C$2:$R$208,8,FALSE)=J38, "", IF(J38="x","+", "-")) | AA38: =IF(VLOOKUP($C38,Intermediate!$C$2:$R$208,9,FALSE)=K38, "", IF(K38="x","+", "-")) | AB38: =IF(VLOOKUP($C38,Intermediate!$C$2:$R$208,10,FALSE)=L38, "", IF(L38="x","+", "-")) | AC38: =IF(VLOOKUP($C38,Intermediate!$C$2:$R$208,11,FALSE)=M38, "", IF(M38="x","+", "-")) | AD38: =IF(VLOOKUP($C38,Intermediate!$C$2:$R$208,12,FALSE)=N38, "", IF(N38="x","+", "-")) | AE38: =IF(VLOOKUP($C38,Intermediate!$C$2:$R$208,13,FALSE)=O38, "", IF(O38="x","+", "-")) | AF38: =IF(VLOOKUP($C38,Intermediate!$C$2:$R$208,14,FALSE)=P38, "", IF(P38="x","+", "-")) | AG38: =IF(VLOOKUP($C38,Intermediate!$C$2:$R$208,15,FALSE)=Q38, "", IF(Q38="x","+", "-")) | AH38: =IF(VLOOKUP($C38,Intermediate!$C$2:$R$208,16,FALSE)=R38, "", IF(R38="x","+", "-"))
